<?xml version="1.0" encoding="utf-8"?>  

<link
    name="End_Effector">
    <inertial>
      <origin
        xyz="7.4313E-05 0.029988 2.7252E-09"
        rpy="0 0 0" />
      <mass
        value="0.088356" />
      <inertia
        ixx="4.5522E-05"
        ixy="2.3345E-08"
        ixz="9.4149E-12"
        iyy="5.0104E-05"
        iyz="5.7432E-12"
        izz="4.5345E-05" />
    </inertial>
    <visual>
      <origin
        xyz="0 0 0"
        rpy="0 0 0" />
      <geometry>
        <mesh
          filename="package://Opstelling samenstelling_URDF.SLDASM/meshes/End_Effector.STL" />
      </geometry>
      <material
        name="">
        <color
          rgba="0.75294 0.75294 0.75294 1" />
      </material>
    </visual>
    <collision>
      <origin
        xyz="0 0 0"
        rpy="0 0 0" />
      <geometry>
        <mesh
          filename="package://Opstelling samenstelling_URDF.SLDASM/meshes/End_Effector.STL" />
      </geometry>
    </collision>
  </link>
  <joint
    name="End_Effector"
    type="revolute">
    <origin
      xyz="-0.049286 0.069 0.019375"
      rpy="-0.59239 0.20244 1.4363" />
    <parent
      link="Link_4" />
    <child
      link="End_Effector" />
    <axis
      xyz="0 1 0" />
    <limit
      lower="-3.14"
      upper="3.14"
      effort="4"
      velocity="6.283" />
  </joint>
